Workbook

Sheet Assumptions
A1: SUDSLY — Core Assumptions & Model Inputs
A2: Yellow = adjustable inputs | Blue text = hardcoded | Black = formulas | Green = cross-sheet links
A3: Wayne State Startup Tech Pitch Competition — March 27, 2026
A5: PRICING TIERS & MARGIN ANALYSIS
A6: Tier | B6: Lbs/Week | C6: Rate/lb | D6: COGS/lb | E6: Net/lb | F6: Gross Margin % | G6: 30-lb Order Net | H6: Annual Benefit
A7: One-Time | B7: Any | C7: 1.95 | D7: =$B$29 -> 1.37 | E7: =C7-D7 -> 0.58 | F7: =(C7-D7)/C7 -> 0.2974359 | G7: =(C7-D7)*30 -> 17.4 | H7: No commitment
A8: Light Contract | B8: 15–25 | C8: 1.85 | D8: =$B$29 -> 1.37 | E8: =C8-D8 -> 0.48 | F8: =(C8-D8)/C8 -> 0.25945946 | G8: =(C8-D8)*30 -> 14.4 | H8: Price Lock (12 mo)
A9: Standard Contract | B9: 26–40 | C9: 1.8 | D9: =$B$29 -> 1.37 | E9: =C9-D9 -> 0.43 | F9: =(C9-D9)/C9 -> 0.23888889 | G9: =(C9-D9)*30 -> 12.9 | H9: Price Lock (12 mo)
A10: Heavy Contract | B10: 41–60 | C10: 1.78 | D10: =$B$29 -> 1.37 | E10: =C10-D10 -> 0.41 | F10: =(C10-D10)/C10 -> 0.23033708 | G10: =(C10-D10)*30 -> 12.3 | H10: Price Lock (12 mo)
A11: Family Contract | B11: 61–80 | C11: 1.75 | D11: =$B$29 -> 1.37 | E11: =C11-D11 -> 0.38 | F11: =(C11-D11)/C11 -> 0.21714286 | G11: =(C11-D11)*30 -> 11.4 | H11: Price Lock (12 mo)
A12: Rush Add-On | B12: Any | C12: 0.8 | D12: — | E12: — | F12: — | G12: — | H12: Surcharge on top of tier
A14: BLENDED RATE CALCULATION
A15: Tier | B15: Mix % | C15: Rate/lb | D15: Weighted Rate
A16: One-Time | B16: 0.3 | C16: =C7 -> 1.95 | D16: =B16*C16 -> 0.585
A17: Light | B17: 0.12 | C17: =C8 -> 1.85 | D17: =B17*C17 -> 0.222
A18: Standard | B18: 0.25 | C18: =C9 -> 1.8 | D18: =B18*C18 -> 0.45
A19: Heavy | B19: 0.18 | C19: =C10 -> 1.78 | D19: =B19*C19 -> 0.3204
A20: Family | B20: 0.12 | C20: =C11 -> 1.75 | D20: =B20*C20 -> 0.21
A21: Rush Uplift (~3%) | B21: 0.03 | C21: =C12 -> 0.8 | D21: =B21*C21 -> 0.024
A22: BLENDED AVG RATE / LB | B22: =SUM(B16:B21) -> 1 | D22: =SUM(D16:D21) -> 1.8114
A24: COST STRUCTURE PER POUND
A25: Cost Component | B25: $/lb | C25: Notes
A26: Laundromat processing | B26: 0.9 | C26: Negotiated rate w/ GP-area partners
A27: Driver fuel & vehicle | B27: 0.22 | C27: Gas + depreciation — efficient routing in tight GP zone
A28: Driver labor | B28: 0.25 | C28: $18/hr, ~25 min round trip
A29: TOTAL VARIABLE COGS / LB | B29: =SUM(B26:B28) -> 1.37 | C29: Every dollar above this = gross margin
A31: BLENDED GROSS MARGIN | B31: =(D22-B29)/D22 -> 0.24367892 | C31: Target: 24%+
A33: CUSTOMER GROWTH ASSUMPTIONS
A34: Metric | B34: Year 1 (2026) | C34: Year 2 (2027) | D34: Year 3 (2028) | E34: Year 4 (2029) | F34: Year 5 (2030) | G34: Rationale
A35: Avg Active Customers | B35: 35 | C35: 160 | D35: 500 | E35: 1300 | F35: 3000 | G35: GP launch → Woods + WSU → Metro
A36: YoY Growth Rate | B36: — | C36: =(C35-B35)/B35 -> 3.5714286 | D36: =(D35-C35)/C35 -> 2.125 | E36: =(E35-D35)/D35 -> 1.6 | F36: =(F35-E35)/E35 -> 1.3076923
A37: Orders / Customer / Month | B37: 2.5 | C37: 2.5 | D37: 2.5 | E37: 2.5 | F37: 2.5 | G37: Weekly + biweekly + one-time mix
A38: Avg Order Weight (lbs) | B38: 30 | C38: 30 | D38: 30 | E38: 30 | F38: 30 | G38: 3-4 person household avg
A39: Orders / Year | B39: =B35*B37*12 -> 1050 | C39: =C35*C37*12 -> 4800 | D39: =D35*D37*12 -> 15000 | E39: =E35*E37*12 -> 39000 | F39: =F35*F37*12 -> 90000 | G39: Customers × orders/mo × 12
A40: Total Lbs / Year | B40: =B39*B38 -> 31500 | C40: =C39*C38 -> 144000 | D40: =D39*D38 -> 450000 | E40: =E39*E38 -> 1170000 | F40: =F39*F38 -> 2700000 | G40: Orders × avg weight
A42: SAAS PARTNER LAUNDROMATS
A43: Metric | B43: Year 1 | C43: Year 2 | D43: Year 3 | E43: Year 4 | F43: Year 5 | G43: Notes
A44: Partner Laundromats | B44: 2 | C44: 5 | D44: 12 | E44: 25 | F44: 50 | G44: Vetted local partners
A45: Monthly SaaS Fee / Partner | B45: 30 | C45: 30 | D45: 30 | E45: 30 | F45: 30 | G45: Dashboard + order mgmt
A46: Annual SaaS Revenue | B46: =B44*B45*12 -> 720 | C46: =C44*C45*12 -> 1800 | D46: =D44*D45*12 -> 4320 | E46: =E44*E45*12 -> 9000 | F46: =F44*F45*12 -> 18000 | G46: Partners × fee × 12
...

Sheet 5-Year P&L
A1: SUDSLY — 5-Year Projected Income Statement
A2: All formulas linked to Assumptions tab | Green = cross-sheet refs
B4: Year 1 (2026 Pilot) | C4: Year 2 (2027) | D4: Year 3 (2028) | E4: Year 4 (2029) | F4: Year 5 (2030)
A6: KEY ASSUMPTIONS (from Assumptions tab)
A7: Blended Revenue Rate ($/lb) | B7: =Assumptions!D22 -> 1.8114 | C7: =Assumptions!D22 -> 1.8114 | D7: =Assumptions!D22 -> 1.8114 | E7: =Assumptions!D22 -> 1.8114 | F7: =Assumptions!D22 -> 1.8114
A8: Variable COGS ($/lb) | B8: =Assumptions!B29 -> 1.37 | C8: =Assumptions!B29 -> 1.37 | D8: =Assumptions!B29 -> 1.37 | E8: =Assumptions!B29 -> 1.37 | F8: =Assumptions!B29 -> 1.37
A9: Avg Order Weight (lbs) | B9: =Assumptions!B38 -> 30 | C9: =Assumptions!C38 -> 30 | D9: =Assumptions!D38 -> 30 | E9: =Assumptions!E38 -> 30 | F9: =Assumptions!F38 -> 30
A10: Avg Active Customers | B10: =Assumptions!B35 -> 35 | C10: =Assumptions!C35 -> 160 | D10: =Assumptions!D35 -> 500 | E10: =Assumptions!E35 -> 1300 | F10: =Assumptions!F35 -> 3000
A11: Orders / Customer / Month | B11: =Assumptions!B37 -> 2.5 | C11: =Assumptions!C37 -> 2.5 | D11: =Assumptions!D37 -> 2.5 | E11: =Assumptions!E37 -> 2.5 | F11: =Assumptions!F37 -> 2.5
A12: SaaS Partner Laundromats | B12: =Assumptions!B44 -> 2 | C12: =Assumptions!C44 -> 5 | D12: =Assumptions!D44 -> 12 | E12: =Assumptions!E44 -> 25 | F12: =Assumptions!F44 -> 50
A13: SaaS Fee / Partner / Month | B13: =Assumptions!B45 -> 30 | C13: =Assumptions!C45 -> 30 | D13: =Assumptions!D45 -> 30 | E13: =Assumptions!E45 -> 30 | F13: =Assumptions!F45 -> 30
A15: REVENUE
A16: Total Orders / Year | B16: =B10*B11*12 -> 1050 | C16: =C10*C11*12 -> 4800 | D16: =D10*D11*12 -> 15000 | E16: =E10*E11*12 -> 39000 | F16: =F10*F11*12 -> 90000
A17: Total Lbs / Year | B17: =B16*B9 -> 31500 | C17: =C16*C9 -> 144000 | D17: =D16*D9 -> 450000 | E17: =E16*E9 -> 1170000 | F17: =F16*F9 -> 2700000
A18: Order Revenue | B18: =B17*B7 -> 57059.1 | C18: =C17*C7 -> 260841.6 | D18: =D17*D7 -> 815130 | E18: =E17*E7 -> 2119338 | F18: =F17*F7 -> 4890780
A19: Partner SaaS Revenue | B19: =B12*B13*12 -> 720 | C19: =C12*C13*12 -> 1800 | D19: =D12*D13*12 -> 4320 | E19: =E12*E13*12 -> 9000 | F19: =F12*F13*12 -> 18000
A20: TOTAL REVENUE | B20: =B18+B19 -> 57779.1 | C20: =C18+C19 -> 262641.6 | D20: =D18+D19 -> 819450 | E20: =E18+E19 -> 2128338 | F20: =F18+F19 -> 4908780
A22: COST OF GOODS SOLD
A23: Variable COGS (laundromat + driver) | B23: =B17*B8 -> 43155 | C23: =C17*C8 -> 197280 | D23: =D17*D8 -> 616500 | E23: =E17*E8 -> 1602900 | F23: =F17*F8 -> 3699000
A24: GROSS PROFIT | B24: =B20-B23 -> 14624.1 | C24: =C20-C23 -> 65361.6 | D24: =D20-D23 -> 202950 | E24: =E20-E23 -> 525438 | F24: =F20-F23 -> 1209780
A25: Gross Margin % | B25: =IF(B20=0,0,B24/B20) -> 0.25310363 | C25: =IF(C20=0,0,C24/C20) -> 0.24886233 | D25: =IF(D20=0,0,D24/D20) -> 0.24766612 | E25: =IF(E20=0,0,E24/E20) -> 0.24687714 | F25: =IF(F20=0,0,F24/F20) -> 0.24645228
A27: FIXED OPERATING COSTS
A28: Auto Insurance | B28: =Assumptions!B52 -> 3600 | C28: =Assumptions!C52 -> 3600 | D28: =Assumptions!D52 -> 7200 | E28: =Assumptions!E52 -> 10800 | F28: =Assumptions!F52 -> 18000
A29: General Liability Ins. | B29: =Assumptions!B53 -> 1200 | C29: =Assumptions!C53 -> 1200 | D29: =Assumptions!D53 -> 1200 | E29: =Assumptions!E53 -> 1200 | F29: =Assumptions!F53 -> 1200
A30: Software & Hosting | B30: =Assumptions!B54 -> 1800 | C30: =Assumptions!C54 -> 1800 | D30: =Assumptions!D54 -> 1800 | E30: =Assumptions!E54 -> 1800 | F30: =Assumptions!F54 -> 1800
A31: Marketing & Cust. Acq. | B31: =Assumptions!B55 -> 4800 | C31: =Assumptions!C55 -> 7200 | D31: =Assumptions!D55 -> 14400 | E31: =Assumptions!E55 -> 24000 | F31: =Assumptions!F55 -> 42000
A32: Legal & Compliance | B32: =Assumptions!B56 -> 1500 | C32: =Assumptions!C56 -> 1500 | D32: =Assumptions!D56 -> 1500 | E32: =Assumptions!E56 -> 1500 | F32: =Assumptions!F56 -> 1500
A33: TOTAL FIXED COSTS | B33: =Assumptions!B57 -> 12900 | C33: =Assumptions!C57 -> 15300 | D33: =Assumptions!D57 -> 26100 | E33: =Assumptions!E57 -> 39300 | F33: =Assumptions!F57 -> 64500
A35: EBITDA
A36: EBITDA | B36: =B24-B33 -> 1724.1 | C36: =C24-C33 -> 50061.6 | D36: =D24-D33 -> 176850 | E36: =E24-E33 -> 486138 | F36: =F24-F33 -> 1145280
A37: EBITDA Margin % | B37: =IF(B20=0,0,B36/B20) -> 0.029839509 | C37: =IF(C20=0,0,C36/C20) -> 0.19060804 | D37: =IF(D20=0,0,D36/D20) -> 0.21581549 | E37: =IF(E20=0,0,E36/E20) -> 0.22841203 | F37: =IF(F20=0,0,F36/F20) -> 0.23331255
A38: Cumulative EBITDA | B38: =B36 -> 1724.1 | C38: =B38+C36 -> 51785.7 | D38: =C38+D36 -> 228635.7 | E38: =D38+E36 -> 714773.7 | F38: =E38+F36 -> 1860053.7
A40: KEY METRICS
A41: Avg Revenue / Order | B41: =IF(B16=0,0,B20/B16) -> 55.027714 | C41: =IF(C16=0,0,C20/C16) -> 54.717 | D41: =IF(D16=0,0,D20/D16) -> 54.63 | E41: =IF(E16=0,0,E20/E16) -> 54.572769 | F41: =IF(F16=0,0,F20/F16) -> 54.542
A42: Net Contribution / Order | B42: =IF(B16=0,0,B24/B16) -> 13.927714 | C42: =IF(C16=0,0,C24/C16) -> 13.617 | D42: =IF(D16=0,0,D24/D16) -> 13.53 | E42: =IF(E16=0,0,E24/E16) -> 13.472769 | F42: =IF(F16=0,0,F24/F16) -> 13.442
A43: Revenue / Customer / Year | B43: =IF(B10=0,0,B20/B10) -> 1650.8314 | C43: =IF(C10=0,0,C20/C10) -> 1641.51 | D43: =IF(D10=0,0,D20/D10) -> 1638.9 | E43: =IF(E10=0,0,E20/E10) -> 1637.1831 | F43: =IF(F10=0,0,F20/F10) -> 1636.26
A45: Rev/EBITDA Chart Data (hidden helper) | B45: Year 1 | C45: Year 2 | D45: Year 3 | E45: Year 4 | F45: Year 5
A46: Total Revenue | B46: =B20 -> 57779.1 | C46: =C20 -> 262641.6 | D46: =D20 -> 819450 | E46: =E20 -> 2128338 | F46: =F20 -> 4908780
A47: EBITDA | B47: =B36 -> 1724.1 | C47: =C36 -> 50061.6 | D47: =D36 -> 176850 | E47: =E36 -> 486138 | F47: =F36 -> 1145280
A48: Gross Margin % | B48: dummy
...

Sheet Investment Plan
A1: SUDSLY — Investment Deployment & Growth Plan
A2: $10,000 Seed — Every Dollar Accounted For
A4: SEED INVESTMENT ($10,000)
A5: Category | B5: Amount | C5: % of Total | D5: Description & Rationale
A6: TECHNOLOGY
A7: App & website development | B7: 3500 | C7: =B7/10000 -> 0.35 | D7: Next.js + React Native + Supabase — Sam builds in-house
A8: QR tracking + scales + tags | B8: 265 | C8: =B8/10000 -> 0.0265 | D8: qrcode npm + 500 tags ($30) + 2 digital scales ($35 ea) + misc
A9: Stripe payment integration | B9: 300 | C9: =B9/10000 -> 0.03 | D9: Test/live mode, subscription billing, hold-and-adjust flow
A10: Twilio SMS (6 months) | B10: 200 | C10: =B10/10000 -> 0.02 | D10: Phone # ($1/mo) + ~1,200 msgs/mo @ $0.0079
A11: Driver portal + admin dashboard | B11: 800 | C11: =B11/10000 -> 0.08 | D11: Mobile driver app, photo upload, admin order mgmt
A12: Domain + hosting buffer (Y1) | B12: 435 | C12: =B12/10000 -> 0.0435 | D12: sudsly.com ($12) + Vercel + contingency buffer
A13: Technology Subtotal | B13: =SUM(B7:B12) -> 5500 | C13: =B13/10000 -> 0.55
A14: MARKETING & ONBOARDING
A15: Launch campaign (Grosse Pointe) | B15: 1000 | C15: =B15/10000 -> 0.1 | D15: Door-to-door materials, flyers, branded bags (50 @ $2.40)
A16: First-order incentives | B16: 500 | C16: =B16/10000 -> 0.05 | D16: Free first pickup for early adopters — up to 50 families
A17: Social media production | B17: 500 | C17: =B17/10000 -> 0.05 | D17: TikTok/IG content, behind-the-scenes, testimonial captures
A18: Laundromat partner onboarding | B18: 500 | C18: =B18/10000 -> 0.05 | D18: Partner materials, training docs, onboarding support
A19: Marketing Subtotal | B19: =SUM(B15:B18) -> 2500 | C19: =B19/10000 -> 0.25
A20: INSURANCE & LEGAL
A21: Commercial auto insurance (4 mo) | B21: 1200 | C21: =B21/10000 -> 0.12 | D21: $300/mo truck rider — required before first pickup
A22: General liability insurance (4 mo) | B22: 400 | C22: =B22/10000 -> 0.04 | D22: $100/mo — damage claims coverage
A23: LLC + legal docs | B23: 400 | C23: =B23/10000 -> 0.04 | D23: MI LLC ($50) + partner contracts + liability policy drafts
A24: Insurance & Legal Subtotal | B24: =SUM(B21:B23) -> 2000 | C24: =B24/10000 -> 0.2
A26: TOTAL SEED INVESTMENT | B26: =B13+B19+B24 -> 10000 | C26: =B26/10000 -> 1 | D26: Every dollar deployed — must equal $10,000
A28: POST-PROFITABILITY REINVESTMENT PLAN
A29: Once Sudsly hits ~$50K annual revenue (mid-Year 2), excess cash funds these in priority order:
A31: Investment | B31: Est. Cost | C31: Priority | D31: Rationale & Impact
A32: Cargo van (used) | B32: 13000 | C32: 1st | D32: Replace truck-bed. Weather-protected, branded. 3x capacity, enables winter.
A33: Marketing reinvestment | B33: 5000 | C33: 2nd | D33: Accelerate GP Woods + WSU expansion. Digital ads, referral bonuses.
A34: First driver hire (part-time) | B34: 8000 | C34: 3rd | D34: Remove CEO from daily routes. $18/hr PT. Full focus on sales & growth.
A35: Second laundromat partner | B35: 1000 | C35: 4th | D35: Redundancy + capacity. No single-point-of-failure on processing.
A36: Route optimization software | B36: 2000 | C36: 5th | D36: Google Maps Directions API. Auto-optimized routes at 8+ stops/day.
A37: TOTAL REINVESTMENT PIPELINE | B37: =SUM(B32:B36) -> 29000 | D37: Funded by operating cash flow — no second round needed
A39: RETURN ON $10K INVESTMENT
A40: Metric | B40: Value
A41: Year 1 Revenue | B41: ='5-Year P&L'!B20 -> 57779.1
A42: Year 2 Revenue | B42: ='5-Year P&L'!C20 -> 262641.6
A43: Year 5 Revenue | B43: ='5-Year P&L'!F20 -> 4908780
A44: Year 5 Cumulative EBITDA | B44: ='5-Year P&L'!F38 -> 1860053.7
A45: 5-Year ROI Multiple | B45: ='5-Year P&L'!F38/10000 -> 186.00537
...
